<?xml version="1.0" ?>
<!-- =================================================================================== -->
<!-- |    This document was autogenerated by xacro from mini_cheetah.urdf              | -->
<!-- |    EDITING THIS FILE BY HAND IS NOT RECOMMENDED                                 | -->
<!-- =================================================================================== -->
<robot name="mini_cheetah">
  <!--  -->
  <!--################################## LINKS ##################################-->
  <!-- LINK ROOT -->
  <link name="link_root">
    <pose> 0 0 0 0 0 0</pose>
  </link>
  <!--  -->
  <!-- LINK BODY -->
  <link name="link_body">
    <pose> 0 0 0 0 0 0</pose>
    <inertial>
      <mass value="5"/>
      <origin rpy="0 0 0" xyz="0 0 0.1"/>
      <inertia ixx="0.03" ixy="0" ixz="0" iyy="0" iyz="0" izz="0"/>
    </inertial>
    <collision>
      <geometry>
        <mesh filename="meshes/mini_cheetah/mini_body.obj"/>
      </geometry>
    </collision>
    <visual>
      <origin rpy="0 0 0" xyz="0 0 0"/>
      <geometry>
        <mesh filename="meshes/mini_cheetah/mini_body.obj"/>
      </geometry>
    </visual>
  </link>
  <!--  -->
  <!-- LINK ABAD -->
  <link name="link_fl_abad">
    <pose> 0 0 0 0 0 0</pose>
    <inertial>
      <mass value="5"/>
      <origin rpy="0 0 0" xyz="0 0 0.1"/>
      <inertia ixx="0.03" ixy="0" ixz="0" iyy="0" iyz="0" izz="0"/>
    </inertial>
    <visual>
      <geometry>
        <mesh filename="meshes/mini_cheetah/mini_abad.obj"/>
      </geometry>
      <!-- <material name="Cyan">
          <color rgba="0 0.0 1.0 1.0"/>
        </material> -->
    </visual>
    <collision>
      <geometry>
        <mesh filename="meshes/mini_cheetah/mini_abad.obj"/>
      </geometry>
    </collision>
  </link>
  <!--  -->
  <!-- JOINT ABAD TO BODY -->
  <joint name="fl_abad_to_body" type="revolute">
    <parent link="link_body"/>
    <child link="link_fl_abad"/>
    <axis xyz="0 1 0"/>
    <origin rpy="0 0.0 -1.5708" xyz="0.139 0.05 0"/>
    <limit effort="1000.0" lower="-1.57079" upper="1.57079" velocity="1"/>
  </joint>
  <!--  -->
  <!-- LINK UPPER -->
  <link name="link_fl_upper">
    <pose> 0 0 0 0 0 0</pose>
    <inertial>
      <mass value="5"/>
      <origin rpy="0 0 0" xyz="0 0 0.1"/>
      <inertia ixx="0.03" ixy="0" ixz="0" iyy="0" iyz="0" izz="0"/>
    </inertial>
    <visual>
      <geometry>
        <mesh filename="meshes/mini_cheetah/mini_upper_link.obj"/>
      </geometry>
      <!-- <material name="Cyan">
          <color rgba="0 0.0 1.0 1.0"/>
        </material> -->
    </visual>
    <collision>
      <geometry>
        <mesh filename="meshes/mini_cheetah/mini_upper_link.obj"/>
      </geometry>
    </collision>
  </link>
  <!--  -->
  <!-- JOINT UPPER TO ABAD -->
  <joint name="fl_upper_to_abad" type="revolute">
    <parent link="link_fl_abad"/>
    <child link="link_fl_upper"/>
    <axis xyz="0 1 0"/>
    <origin rpy="3.14159 0.0 1.5708" xyz="-0.0613 0.0575 0"/>
    <limit effort="1000.0" lower="-1.57079" upper="1.57079" velocity="1"/>
  </joint>
  <!--  -->
  <!-- LINK LOWER -->
  <link name="link_fl_lower">
    <pose> 0 0 0 0 0 0</pose>
    <inertial>
      <mass value="5"/>
      <origin rpy="0 0 0" xyz="0 0 0.1"/>
      <inertia ixx="0.03" ixy="0" ixz="0" iyy="0" iyz="0" izz="0"/>
    </inertial>
    <visual>
      <geometry>
        <mesh filename="meshes/mini_cheetah/mini_lower_link.obj"/>
      </geometry>
      <!-- <material name="Cyan">
          <color rgba="0 0.0 1.0 1.0"/>
        </material> -->
    </visual>
    <collision>
      <geometry>
        <mesh filename="meshes/mini_cheetah/mini_lower_link.obj"/>
      </geometry>
    </collision>
  </link>
  <!--  -->
  <!-- JOINT LOWER TO UPPER -->
  <joint name="fl_lower_to_upper" type="revolute">
    <parent link="link_fl_upper"/>
    <child link="link_fl_lower"/>
    <axis xyz="0 1 0"/>
    <origin rpy="0 0.0 0" xyz="-0.20835 -0.0011 0"/>
    <limit effort="1000.0" lower="-1.57079" upper="1.57079" velocity="1"/>
  </joint>
  <!--  -->
  <!-- LINK ABAD -->
  <link name="link_fr_abad">
    <pose> 0 0 0 0 0 0</pose>
    <inertial>
      <mass value="5"/>
      <origin rpy="0 0 0" xyz="0 0 0.1"/>
      <inertia ixx="0.03" ixy="0" ixz="0" iyy="0" iyz="0" izz="0"/>
    </inertial>
    <visual>
      <geometry>
        <mesh filename="meshes/mini_cheetah/mini_abad.obj"/>
      </geometry>
      <!-- <material name="Cyan">
          <color rgba="0 0.0 1.0 1.0"/>
        </material> -->
    </visual>
    <collision>
      <geometry>
        <mesh filename="meshes/mini_cheetah/mini_abad.obj"/>
      </geometry>
    </collision>
  </link>
  <!--  -->
  <!-- JOINT ABAD TO BODY -->
  <joint name="fr_abad_to_body" type="revolute">
    <parent link="link_body"/>
    <child link="link_fr_abad"/>
    <axis xyz="0 1 0"/>
    <origin rpy="0 3.14159 -1.5708" xyz="0.139 -0.05 0"/>
    <limit effort="1000.0" lower="-1.57079" upper="1.57079" velocity="1"/>
  </joint>
  <!--  -->
  <!-- LINK UPPER -->
  <link name="link_fr_upper">
    <pose> 0 0 0 0 0 0</pose>
    <inertial>
      <mass value="5"/>
      <origin rpy="0 0 0" xyz="0 0 0.1"/>
      <inertia ixx="0.03" ixy="0" ixz="0" iyy="0" iyz="0" izz="0"/>
    </inertial>
    <visual>
      <geometry>
        <mesh filename="meshes/mini_cheetah/mini_upper_link.obj"/>
      </geometry>
      <!-- <material name="Cyan">
          <color rgba="0 0.0 1.0 1.0"/>
        </material> -->
    </visual>
    <collision>
      <geometry>
        <mesh filename="meshes/mini_cheetah/mini_upper_link.obj"/>
      </geometry>
    </collision>
  </link>
  <!--  -->
  <!-- JOINT UPPER TO ABAD -->
  <joint name="fr_upper_to_abad" type="revolute">
    <parent link="link_fr_abad"/>
    <child link="link_fr_upper"/>
    <axis xyz="0 1 0"/>
    <origin rpy="3.14159 0.0 1.5708" xyz="-0.0613 0.0575 0"/>
    <limit effort="1000.0" lower="-1.57079" upper="1.57079" velocity="1"/>
  </joint>
  <!--  -->
  <!-- LINK LOWER -->
  <link name="link_fr_lower">
    <pose> 0 0 0 0 0 0</pose>
    <inertial>
      <mass value="5"/>
      <origin rpy="0 0 0" xyz="0 0 0.1"/>
      <inertia ixx="0.03" ixy="0" ixz="0" iyy="0" iyz="0" izz="0"/>
    </inertial>
    <visual>
      <geometry>
        <mesh filename="meshes/mini_cheetah/mini_lower_link.obj"/>
      </geometry>
      <!-- <material name="Cyan">
          <color rgba="0 0.0 1.0 1.0"/>
        </material> -->
    </visual>
    <collision>
      <geometry>
        <mesh filename="meshes/mini_cheetah/mini_lower_link.obj"/>
      </geometry>
    </collision>
  </link>
  <!--  -->
  <!-- JOINT LOWER TO UPPER -->
  <joint name="fr_lower_to_upper" type="revolute">
    <parent link="link_fr_upper"/>
    <child link="link_fr_lower"/>
    <axis xyz="0 1 0"/>
    <origin rpy="0 3.14159 0" xyz="-0.20835 -0.0011 0"/>
    <limit effort="1000.0" lower="-1.57079" upper="1.57079" velocity="1"/>
  </joint>
  <!--  -->
  <!-- LINK ABAD -->
  <link name="link_bl_abad">
    <pose> 0 0 0 0 0 0</pose>
    <inertial>
      <mass value="5"/>
      <origin rpy="0 0 0" xyz="0 0 0.1"/>
      <inertia ixx="0.03" ixy="0" ixz="0" iyy="0" iyz="0" izz="0"/>
    </inertial>
    <visual>
      <geometry>
        <mesh filename="meshes/mini_cheetah/mini_abad.obj"/>
      </geometry>
      <!-- <material name="Cyan">
          <color rgba="0 0.0 1.0 1.0"/>
        </material> -->
    </visual>
    <collision>
      <geometry>
        <mesh filename="meshes/mini_cheetah/mini_abad.obj"/>
      </geometry>
    </collision>
  </link>
  <!--  -->
  <!-- JOINT ABAD TO BODY -->
  <joint name="bl_abad_to_body" type="revolute">
    <parent link="link_body"/>
    <child link="link_bl_abad"/>
    <axis xyz="0 1 0"/>
    <origin rpy="0 3.14159 1.5708" xyz="-0.139 0.05 0"/>
    <limit effort="1000.0" lower="-1.57079" upper="1.57079" velocity="1"/>
  </joint>
  <!--  -->
  <!-- LINK UPPER -->
  <link name="link_bl_upper">
    <pose> 0 0 0 0 0 0</pose>
    <inertial>
      <mass value="5"/>
      <origin rpy="0 0 0" xyz="0 0 0.1"/>
      <inertia ixx="0.03" ixy="0" ixz="0" iyy="0" iyz="0" izz="0"/>
    </inertial>
    <visual>
      <geometry>
        <mesh filename="meshes/mini_cheetah/mini_upper_link.obj"/>
      </geometry>
      <!-- <material name="Cyan">
          <color rgba="0 0.0 1.0 1.0"/>
        </material> -->
    </visual>
    <collision>
      <geometry>
        <mesh filename="meshes/mini_cheetah/mini_upper_link.obj"/>
      </geometry>
    </collision>
  </link>
  <!--  -->
  <!-- JOINT UPPER TO ABAD -->
  <joint name="bl_upper_to_abad" type="revolute">
    <parent link="link_bl_abad"/>
    <child link="link_bl_upper"/>
    <axis xyz="0 1 0"/>
    <origin rpy="3.14159 3.14159 1.5708" xyz="-0.0613 0.0575 0"/>
    <limit effort="1000.0" lower="-1.57079" upper="1.57079" velocity="1"/>
  </joint>
  <!--  -->
  <!-- LINK LOWER -->
  <link name="link_bl_lower">
    <pose> 0 0 0 0 0 0</pose>
    <inertial>
      <mass value="5"/>
      <origin rpy="0 0 0" xyz="0 0 0.1"/>
      <inertia ixx="0.03" ixy="0" ixz="0" iyy="0" iyz="0" izz="0"/>
    </inertial>
    <visual>
      <geometry>
        <mesh filename="meshes/mini_cheetah/mini_lower_link.obj"/>
      </geometry>
      <!-- <material name="Cyan">
          <color rgba="0 0.0 1.0 1.0"/>
        </material> -->
    </visual>
    <collision>
      <geometry>
        <mesh filename="meshes/mini_cheetah/mini_lower_link.obj"/>
      </geometry>
    </collision>
  </link>
  <!--  -->
  <!-- JOINT LOWER TO UPPER -->
  <joint name="bl_lower_to_upper" type="revolute">
    <parent link="link_bl_upper"/>
    <child link="link_bl_lower"/>
    <axis xyz="0 1 0"/>
    <origin rpy="0 0.0 0" xyz="-0.20835 -0.0011 0"/>
    <limit effort="1000.0" lower="-1.57079" upper="1.57079" velocity="1"/>
  </joint>
  <!--  -->
  <!-- LINK ABAD -->
  <link name="link_br_abad">
    <pose> 0 0 0 0 0 0</pose>
    <inertial>
      <mass value="5"/>
      <origin rpy="0 0 0" xyz="0 0 0.1"/>
      <inertia ixx="0.03" ixy="0" ixz="0" iyy="0" iyz="0" izz="0"/>
    </inertial>
    <visual>
      <geometry>
        <mesh filename="meshes/mini_cheetah/mini_abad.obj"/>
      </geometry>
      <!-- <material name="Cyan">
          <color rgba="0 0.0 1.0 1.0"/>
        </material> -->
    </visual>
    <collision>
      <geometry>
        <mesh filename="meshes/mini_cheetah/mini_abad.obj"/>
      </geometry>
    </collision>
  </link>
  <!--  -->
  <!-- JOINT ABAD TO BODY -->
  <joint name="br_abad_to_body" type="revolute">
    <parent link="link_body"/>
    <child link="link_br_abad"/>
    <axis xyz="0 1 0"/>
    <origin rpy="0 0.0 1.5708" xyz="-0.139 -0.05 0"/>
    <limit effort="1000.0" lower="-1.57079" upper="1.57079" velocity="1"/>
  </joint>
  <!--  -->
  <!-- LINK UPPER -->
  <link name="link_br_upper">
    <pose> 0 0 0 0 0 0</pose>
    <inertial>
      <mass value="5"/>
      <origin rpy="0 0 0" xyz="0 0 0.1"/>
      <inertia ixx="0.03" ixy="0" ixz="0" iyy="0" iyz="0" izz="0"/>
    </inertial>
    <visual>
      <geometry>
        <mesh filename="meshes/mini_cheetah/mini_upper_link.obj"/>
      </geometry>
      <!-- <material name="Cyan">
          <color rgba="0 0.0 1.0 1.0"/>
        </material> -->
    </visual>
    <collision>
      <geometry>
        <mesh filename="meshes/mini_cheetah/mini_upper_link.obj"/>
      </geometry>
    </collision>
  </link>
  <!--  -->
  <!-- JOINT UPPER TO ABAD -->
  <joint name="br_upper_to_abad" type="revolute">
    <parent link="link_br_abad"/>
    <child link="link_br_upper"/>
    <axis xyz="0 1 0"/>
    <origin rpy="3.14159 3.14159 1.5708" xyz="-0.0613 0.0575 0"/>
    <limit effort="1000.0" lower="-1.57079" upper="1.57079" velocity="1"/>
  </joint>
  <!--  -->
  <!-- LINK LOWER -->
  <link name="link_br_lower">
    <pose> 0 0 0 0 0 0</pose>
    <inertial>
      <mass value="5"/>
      <origin rpy="0 0 0" xyz="0 0 0.1"/>
      <inertia ixx="0.03" ixy="0" ixz="0" iyy="0" iyz="0" izz="0"/>
    </inertial>
    <visual>
      <geometry>
        <mesh filename="meshes/mini_cheetah/mini_lower_link.obj"/>
      </geometry>
      <!-- <material name="Cyan">
          <color rgba="0 0.0 1.0 1.0"/>
        </material> -->
    </visual>
    <collision>
      <geometry>
        <mesh filename="meshes/mini_cheetah/mini_lower_link.obj"/>
      </geometry>
    </collision>
  </link>
  <!--  -->
  <!-- JOINT LOWER TO UPPER -->
  <joint name="br_lower_to_upper" type="revolute">
    <parent link="link_br_upper"/>
    <child link="link_br_lower"/>
    <axis xyz="0 1 0"/>
    <origin rpy="0 3.14159 0" xyz="-0.20835 -0.0011 0"/>
    <limit effort="1000.0" lower="-1.57079" upper="1.57079" velocity="1"/>
  </joint>
  <!--  -->
  <!--############################################################################-->
  <!--################################## JOINTS ##################################-->
  <!-- JOINT BODY TO ROOT -->
  <joint name="root_to_body" type="fixed">
    <parent link="link_root"/>
    <child link="link_body"/>
    <origin rpy="0 0 0" xyz="0 0 0"/>
  </joint>
  <!--  -->
  <!--############################################################################-->
  <!--################################## PLUGINS ##################################-->
  <gazebo>
    <plugin filename="libgazebo_ros_control.so" name="gazebo_ros_control">
      <robotNamespace>/mini_cheetah</robotNamespace>
    </plugin>
  </gazebo>
  <!-- servo 0 -->
  <transmission name="joint_0">
    <type>transmission_interface/SimpleTransmision</type>
    <actuator name="joint_0">
      <mechanicalReduction>1</mechanicalReduction>
    </actuator>
    <joint name="fr_abad_to_body">
      <hardwareInterface>hardware_interface/EffortJointInterface</hardwareInterface>
    </joint>
  </transmission>
  <!--  -->
  <!-- servo 1 -->
  <transmission name="joint_1">
    <type>transmission_interface/SimpleTransmision</type>
    <actuator name="joint_1">
      <mechanicalReduction>1</mechanicalReduction>
    </actuator>
    <joint name="fr_upper_to_abad">
      <hardwareInterface>hardware_interface/EffortJointInterface</hardwareInterface>
    </joint>
  </transmission>
  <!--  -->
</robot>

